from fastapi import Request, status
from fastapi.responses import JSONResponse
from sqlalchemy.exc import SQLAlchemyError
from fastapi.exceptions import ResponseValidationError

class APIError(Exception):
    def __init__(self, status_code: int, detail: str):
        self.status_code = status_code
        self.detail = detail

async def validation_error_handler(request: Request, exc: ResponseValidationError):
    return JSONResponse(
        status_code=status.HTTP_422_UNPROCESSABLE_ENTITY,
        content={
            "success": False,
            "message": "Error de validaci√≥n",
            "errors": exc.errors(),
            "data": None
        }
    )

async def sqlalchemy_error_handler(request: Request, exc: SQLAlchemyError):
    return JSONResponse(
        status_code=status.HTTP_500_INTERNAL_SERVER_ERROR,
        content={
            "success": False,
            "message": "Error de base de datos",
            "error": str(exc),
            "data": None
        }
    )

async def api_error_handler(request: Request, exc: APIError):
    return JSONResponse(
        status_code=exc.status_code,
        content={
            "success": False,
            "message": exc.detail,
            "data": None
        }
    )

async def general_exception_handler(request: Request, exc: Exception):
    return JSONResponse(
        status_code=status.HTTP_500_INTERNAL_SERVER_ERROR,
        content={
            "success": False,
            "message": "Error interno del servidor",
            "error": str(exc),
            "data": None
        }
    )